Workbook

Sheet Assessment guide
A1: The Scale | J1: Priority Weight — High / Med / Low
A2: Score | B2: Label | C2: Meaning | J2: Priority | K2: Weight | L2: Meaning
A3: 1 | B3: ❌ Not Exists | C3: Nothing provided, no evidence it exists | J3: 🔴 High | K3: 3 | L3: Handover cannot proceed without this. If score ≤ 2, it's a hard blocker.
A4: 2 | B4: ⚠️ Incomplete | C4: Partially exists but missing critical parts | J4: 🟡 Med | K4: 2 | L4: Important but recoverable. If score ≤ 2, flag it and resolve in Sprint 0.
A5: 3 | B5: 🔶 Acceptable | C5: Exists and understandable, but needs cleanup | J5: 🟢 Low | K5: 1 | L5: Nice to have. If missing, document it as a risk and move on.
A6: 4 | B6: ✅ Good | C6: Clear, complete, usable by a new team member
A7: 5 | B7: 🌟 Excellent | C7: Thorough, verified, and signed off by reviewer
A11: Minimum Score to Proceed with Handover
A12: Section | B12: Min. Score to Accept | C12: Logic
A13: Section 1 — Knowledge Capture | B13: Average ≥ 3.5 | C13: If key knowledge items score 1–2, the current dev hasn't transferred enough
A14: Section 2 — Documents | B14: Average ≥ 3.0 | C14: At least 3 of 4 docs must exist in usable form
A15: Section 3 — Gap Analysis | B15: All actions defined | C15: Every gap must have a named owner and timeline, not just an action statement
A19: Decision Gate
A20: Add up scores across all items and use this to make the go/no-go call:
A21: Total Average | B21: Decision | C21: What to Do
A22: 4.0 – 5.0 | B22: ✅ Proceed | C22: Handover can begin formally
A23: 3.0 – 3.9 | B23: 🔶 Proceed with Conditions | C23: Accept but flag the low-scoring items as blockers to resolve in Sprint 0
A24: 2.0 – 2.9 | B24: ⚠️ Hold | C24: Do not accept until critical items reach score 3+
A25: Below 2.0 | B25: ❌ Reject | C25: Handover is not ready — current dev must do more work first

Sheet General
A1: Project Name: | B1: Payroll CTD | D1: Start Date: | E1: 46204
A2: Sponsor: | B2: CTD | D2: End Date: | E2: 46251
A3: Project Manager: | B3: Thoai, Dao Duy | D3: Current Stage:
A4: Current Tenant Build: | B4: UAT | D4: Overall Project Status: | E4: AMBER
A6: STREAM-WISE STATUS SUMMARY
A7: Workstream | B7: Total Items/Scope | C7: Completed | D7: In Progress | E7: % Complete
A8: Functional | E8: =D8/B8 -> #DIV/0!
A9: Data | E9: =D9/B9 -> #DIV/0!
A10: Integrations | E10: =D10/B10 -> #DIV/0!
A11: Infrastructure | E11: =D11/B11 -> #DIV/0!
A13: System | B13: URL | C13: Access info
A14: SFTP
A15: UAT
A16: PROD
A20: PROJECT CRITICAL RISKS & ISSUES LOG
A21: Risk/Issue ID | B21: Description | C21: Impact Level | D21: Mitigation Strategy | E21: Owner
A27: Workday APIs & RaaS
A28: No | B28: Name | C28: Type | D28: Owner & URL | E28: Status | F28: Payroll Use / Reason
A29: 1 | B29: Get_Workers (bulk) | C29: SOAP HR v44.1 | D29: /ccx/service/{tenant}/Human_Resources/v44.1 op Get_Workers | E29: 🟢 Synced — 4,179 rows | F29: Employee roster, org, comp, dependents, events
A30: 2 | B30: Get_Workers (single) | C30: SOAP HR v44.1 | D30: /ccx/service/{tenant}/Human_Resources/v44.1 op Get_Workers | E30: 🟢 Working | F30: Single employee on demand
A31: 3 | B31: Get_Workers (+comp) | C31: SOAP HR v44.1 | D31: /ccx/service/{tenant}/Human_Resources/v44.1 op Get_Workers w/ Include_Compensation=true | E31: 🟢 Synced — 8,581 rows | F31: Salary + allowance plans per worker
A32: 4 | B32: Get_Workers (+dependents) | C32: SOAP HR v44.1 | D32: /ccx/service/{tenant}/Human_Resources/v44.1 op Get_Workers w/ Include_Related_Persons=true | E32: 🟢 Synced — 9,154 rows | F32: Dependent records
A33: 5 | B33: Get_Workers (+events) | C33: SOAP HR v44.1 | D33: /ccx/service/{tenant}/Human_Resources/v44.1 op Get_Workers w/ Include_Transaction_Log_Data=true | E33: 🟢 Synced — 390,880 rows (not payroll-consumed) | F33: BP/event audit trail
A34: 6 | B34: Get_Organizations | C34: SOAP HR v44.1 | D34: /ccx/service/{tenant}/Human_Resources/v44.1 op Get_Organizations | E34: 🟢 Synced — 1,975 rows | F34: Cost center / org hierarchy
A35: 7 | B35: Get_Holiday_Calendars | C35: SOAP HR v44.1 | D35: /ccx/service/{tenant}/Human_Resources/v44.1 op Get_Holiday_Calendars | E35: 🟢 Synced — 20 rows | F35: Holiday dates → OT multipliers
A36: 8 | B36: Get_Time_Requests | C36: SOAP Time_Tracking v44.1 | D36: /ccx/service/{tenant}/Time_Tracking/v44.1 op Get_Time_Requests | E36: 🟢 Synced — 106 rows | F36: OT Plan requests (hours + approval)
A37: 9 | B37: CTD_-_Monthly_Attendance_Report_-_Copy | C37: RaaS customreport2 | D37: hongnl@coteccons.vn /ccx/service/customreport2/{tenant}/{owner}/CTD_-_Monthly_Attendance_Report_-_Copy | E37: 🟡 Stale — 6,935 rows, timed out on wide-range re-sync | F37: Attendance, OT hours, leave days
A38: 10 | B38: CTD_-_Compensation_Changes_Report | C38: RaaS customreport2 | D38: hongnl@coteccons.vn /ccx/service/customreport2/{tenant}/{owner}/CTD_-_Compensation_Changes_Report | E38: 🟢 Synced — 10,692 rows | F38: Salary/allowance mid-month changes
A39: 11 | B39: Compensation_Profile_-_Allowances | C39: RaaS customreport2 | D39: /ccx/service/customreport2/{tenant}/wd-support/Compensation_Profile_-_Allowances | E39: 🟢 Synced — 4,157 rows | F39: Current allowance snapshot
A40: 12 | B40: Get_Calculated_Time_Blocks | C40: SOAP Time_Tracking v44.1 | E40: 🔴 Blocked — security domain not granted | F40: Would give OT actual hours
A41: 13 | B41: CTD_-_List_Detail_of_Work_History | C41: RaaS customreport2 | E41: 🔴 Blocked — tenant report permission issue | F41: Would give allowance event history
A42: 14 | B42: All_Worker_Time_Off | C42: RaaS systemreport2 | E42: 🔴 Blocked — every param rejected | F42: Would give time-off/leave data
A43: 15 | B43: CTD_-_Time_Off_Balance_For_Payout_-_Copy | C43: RaaS customreport2 | E43: 🟠 Waiting — needs Business_Object value from user | F43: Would give leave-balance-for-payout data
A44: 16 | B44: Get_Time_Off_Plan_Balances | C44: SOAP Absence_Management v44.1/v46.1 | E44: 🔍 Verified to exist — not yet implemented | F44: Would give leave balances directly, no blocking param
A45: 17 | B45: Compensation_Changes_Report (old, owner-less) | C45: RaaS systemreport2 | E45: ⚪ Abandoned — replaced by #10 | F45: —
A46: 18 | B46: 6x SOAP ops (HR v46.1: Get_Employee_Employment_Info, Get_Employee_Personal_Info, Get_Employee_Related_Persons, Get_Former_Workers, Get_Period_Reporting_Calendars, Get_Worker_Event_History) | C46: SOAP HR v46.1 | E46: ⚪ Abandoned — replaced by Get_Workers response-group flags | F46: —
A47: 19 | B47: CTD - Night/Sunday Meal & Regular Audit | C47: RaaS ? | E47: ⚫ Not found — need real report name | F47: Unknown
A48: 20 | B48: CTD - Absence Report | C48: RaaS ? | E48: ⚫ Not found — need real report name | F48: Unknown
A49: 21 | B49: 14× write operations (HireEmployee, ChangeJob, etc., internal/workday/write.go) | C49: SOAP HR v44.1 | E49: 📝 Coded, not wired to any REST endpoint | F49: Not payroll-read; write-back only

Sheet Resources
A1: Suggested Resources — Phase 1 (Internal CTD)
A2: IT Team | B2: IT Team
A3: # | B3: Name | C3: Email | D3: Role
B4: Nguyễn Phi Thoàn | C4: thoannp@coteccons.vn | D4: Functional Lead
B5: Đào Duy Thoại | C5: hoangdd@coteccons.vn | D5: Technical Lead
B6: Dương Phạm Thành Công | C6: congdpt@coteccons.vn | D6: Functional | E6: review design, field mapping, integrations
B7: Nguyễn Lâm Khánh Quỳnh | C7: quynhnlk@coteccons.vn | D7: Functional | E7: review design, field mapping, transfer knowledge
B8: Trần Văn Hậu | C8: hautv01@coteccons.vn | D8: Integration | E8: transfer knowledge, integrations
B9: Trần Bùi Hoàng Gia | C9: giatbh@coteccons.vn | D9: Back-end dev | E9: review system, infra, code quality, get onboarding
B10: Nguyễn Thiện Nhân | C10: nhannt02@cotecconsgroupvn.onmicrosoft.com | D10: Front-end dev | E10: review system, infra, code quality, get onboarding
B11: Nguyễn Lê Thanh Trúc | C11: trucnlt@cotecconsgroupvn.onmicrosoft.com | D11: QE | E11: review UI, tool quality, rule quality, documents
A14: HC
A15: # | B15: Name | C15: Email | D15: Function
B16: Phạm Thị Ánh Nguyệt | C16: nguyetpta@coteccons.vn | D16: Core HCM (com change, termination, review contract...), Compensation
B17: Bùi Thị Thanh | C17: thanh.bui@unicons.vn | D17: Absence, Time Tracking, Core HCM (Job Change, Com Change)

Sheet Sys flow_Payroll
A1: LUỒNG TẠO VÀ XỬ LÝ PAYSLIP (recommendation)
A3: 1. Kéo dữ liệu mỗi tháng từ Workday & CTD HRIS
A4: - Định kỳ mỗi tháng ngày chốt công (20)/ thủ công kéo dữ liệu từ hệ thống Workday và CTD HRIS về CTD Payroll Engine bao gồm:
A5: + CTD HRIS: Employees' expenses
A6: + Workday: Employee information, Compensation plans, Time Tracking and Absences
A7: - Tại Payroll Engine: Tính toán Allowance dựa theo thông tin Onboard, Offboard, Enter times, ...
A8: + Cần HR cung cấp các trường hợp loại trừ, phát sinh (nếu có) | G8: Ví dụ: Tiền cơm OT, trường hợp không dc hưởng phụ cấp (based on Onboard/Offboard), ...
A10: 2. Kiểm tra thông tin và tính Payslip cho toàn bộ nhân viên
A11: - HR review lại các thông tin về Allowance, Enter times, Expenses
A12: + Click Download <Allowances/Enter times/ Expense> report lấy các file Excel tương ứng về kiểm tra
A13: + Cần HR cung cấp/ xác nhận các template report tương ứng từng object | H13: (1)
A14: - Click Mass approve sau khi review các data ở mỗi object chính xác
A15: - Tạo Payroll period, mặc định 25 của tháng trước đến 25 tháng hiện tại
A16: - Tại Payroll period view, click Generate Payslips để hệ thống tạo các payslips trong period.
A17: + Cần HR cung cấp/ xác nhận cấu trúc lương và các công thức lương được dùng để tính Payroll
A19: 3. Upload để chỉnh các ad-hoc cases
A20: - Tại Payroll period view, sau khi Payslips được tạo. Click Download payroll report
A21: + Cần HR cung cấp/ xác nhận Payroll template | F21: (2)
A22: - Tại Payroll period view, click Update payslip xuất hiện pop-up cho phép HR upload Payroll file với các mục cần thay đổi
A23: - Tại Payroll period view, click Re-compute payslips để reset lại payslip theo cấu trúc lương của hệ thống
A25: 4. Xác nhận và gửi payslip
A26: - Sau khi kiểm tra toàn bộ dữ liệu và đảm bảo tính chính xác. Tại Payroll period view, click Approved để xác nhận và khoá thay đổi toàn bộ Payslip
A27: - Khi Payroll period đã done, click Push to WD đẩy các Payslip vào SFTP để đưa lên WD.
A28: + Cần HR cung cấp/ xác nhận Payslip template | F28: (3)
A29: - Các template cần đẩy lên WD bao gồm: (1), (2) và (3)
A31: 5. Lưu ý
A32: Tại màn hình Payroll period: | H32: Tại các màn hình Allowance/ Enter times/ Expense:
A33: Các trạng thái cần có: New -> Computed ->Done -> Pushed -> Cancel | H33: Các trạng thái cần ở mỗi object: Draft -> Approved -> Archived
A34: - New: | H34: - Draft:
B35: + Compute Payslip button: | I35: + Approved button:
A36: - Computed: | I36: + Archived button:
B37: + Download payroll button: | H37: - Archived:
B38: + Update payslip button: | I38: + Unarchived button:
B39: + Re-compute payslips button: | H39: - Button Print report ở các trạng thái Draft/ Approved
B40: + Approved button:
A41: - Done:
B42: + Push to WD button:
A43: - Button Cancel ở các trạng thái New/ Computed/ Done

Sheet Allowance Rule + Except
A1: Rule
A2: # | B2: Compensation plan | D2: Level 1 | E2: Level 2-3 | F2: Level 4 | G2: Level 5 | H2: Level 6 | I2: Level 7 | J2: Level 8
A3: 1 | B3: Tel | D3: 300 | E3: 400 | F3: 400 | G3: 600 | H3: 800 | I3: 1tr | J3: 1tr
A4: 2 | B4: Car | C4: Not BOD | I4: 10tr | J4: 25tr
C5: BOD | J5: 35tr
A6: 3 | B6: Petro | C6: Not site | D6: 800 with approval
C7: Site | E7: 1tr | F7: 1tr | G7: 1tr | H7: 1tr
A8: 4 | B8: Responsibility | C8: Security Team Leader | D8: 1tr2
C9: Deputy Security Team Leader | D9: 800k
C10: Acting Deputy Site Manager | D10: 5tr
C11: Acting Site Manager | D11: 8tr
C12: Acting Project Director | D12: 15tr
A13: 5 | B13: Transportation | C13: 30-100 km, central | E13: 1tr2 | F13: 1tr5 | G13: 1tr5 | H13: 1tr9
C14: 100-400 km, central | E14: 2tr1 | F14: 2tr6 | G14: 2tr6 | H14: 2tr9
C15: 400-1k km, central | E15: 4tr | F15: 4tr5 | G15: 4tr5 | H15: 5tr
C16: 30-100 km, not central | E16: 1tr2 | F16: 1tr5 | G16: 1tr5 | H16: 1tr9
C17: 100-400 km, not central | E17: 2tr1 | F17: 2tr6 | G17: 2tr6 | H17: 2tr9
C18: 400-1k km, not central | E18: 4tr8 | F18: 5tr3 | G18: 5tr3 | H18: 8tr6
C19: > 1k km, not central | E19: 5tr7 | F19: 7tr6 | G19: 7tr6 | H19: 13tr2
A20: 6 | B20: Meal | C20: Security staff | D20: 2 x 45k
C21: Non-project | D21: 1 x 45k
C22: Project < 30km | D22: 2 x 45k
C23: Project >= 30k | D23: 3 x 45k
A24: Exception
A25: # | B25: Compensation plan | C25: Exception | D25: Handle | E25: Compute
A26: 1 | B26: Transportation | C26: New Hire employee has the same permanent residence province as their working location | D26: WD | E26: Amount = 0
A27: 2
A28: 3
A29: 4
A30: 5
A31: 6

Sheet Payroll structure
A1: code | B1: category | C1: vis | D1: seq | E1: type | F1: tax | G1: source -tobe | H1: tên | I1: công thức hiện tại | J1: công thức (param hoá) | K1: Sample payroll fomula - explain in text (red highlighed is the diff bw col H vs J) | L1: Ghi chú (agent) | L1: Ghi chú (agent) | M1: Matched? (Y/N) | N1: HR Confirm | O1: Confirmed by | P1: Confirmed Date | U1: PARAM | V1: Giá trị | W1: Dự đoán ý nghĩa
A2: STD_DAYS | C2: =SUBSTITUTE(ADDRESS(1, MATCH(A2, 'Payroll Mar 2026'!$8:$8, 0), 4), "1", "") -> W | D2: 100 | E2: input | H2: Công chuẩn | Q2: Legend | U2: CONTRACT_TYPE | V2: (input) | W2: Loại hợp đồng "Chính thức"/"Thử việc" — biến điều kiện cho các nhánh IF
A3: PROB_DAYS | B3: TIME_TRACKING | C3: =SUBSTITUTE(ADDRESS(1, MATCH(A3, 'Payroll Mar 2026'!$8:$8, 0), 4), "1", "") -> X | D3: 110 | E3: input | G3: WD API | H3: Ngày công thử việc | Q3: Key | R3: value | S3: Source | T3: note | U3: SI_CAP | V3: 50600000 | W3: Trần lương đóng BHXH/BHYT/TNLĐ = 50.600.000 (số chuẩn HR xác nhận) — dùng cho r19,71,73,104,106,108
A4: OFFICIAL_DAYS | B4: TIME_TRACKING | C4: =SUBSTITUTE(ADDRESS(1, MATCH(A4, 'Payroll Mar 2026'!$8:$8, 0), 4), "1", "") -> Y | D4: 120 | E4: input | G4: WD API | H4: Ngày công chính thức | Q4: type | R4: input | S4: Excel compute | U4: HI_CAP (BỎ) | W4: Đã gộp vào SI_CAP 50.6M — không dùng riêng trần 46.8M nữa
A5: ACTUAL_DAYS | C5: =SUBSTITUTE(ADDRESS(1, MATCH(A5, 'Payroll Mar 2026'!$8:$8, 0), 4), "1", "") -> #N/A | D5: 125 | E5: formula | H5: Tổng ngày công thực tế | S5: WD API | U5: UI_CAP | V5: 106200000 | W5: Trần lương đóng BHTN = 20x LTT vùng I (5.310.000)
A6: PAID_LEAVE_DAYS | B6: TIME_TRACKING | C6: =SUBSTITUTE(ADDRESS(1, MATCH(A6, 'Payroll Mar 2026'!$8:$8, 0), 4), "1", "") -> Z | D6: 130 | E6: input | G6: WD API | H6: Nghỉ phép năm | S6: WD API - CTD Payroll | U6: MEAL_RATE | V6: 45000 | W6: Đơn giá tiền ăn mỗi suất/ngày công
A7: HOLIDAY_DAYS | B7: TIME_TRACKING | C7: =SUBSTITUTE(ADDRESS(1, MATCH(A7, 'Payroll Mar 2026'!$8:$8, 0), 4), "1", "") -> AA | D7: 135 | E7: input | G7: WD API | H7: Nghỉ lễ, tết | S7: CTD HRIS | U7: MEAL_NONTAX_CAP | V7: 1200000 | W7: Trần tiền ăn giữa ca miễn thuế TNCN/tháng
A8: COMP_DAYS | B8: TIME_TRACKING | C8: =SUBSTITUTE(ADDRESS(1, MATCH(A8, 'Payroll Mar 2026'!$8:$8, 0), 4), "1", "") -> AB | D8: 137 | E8: input | G8: WD API | H8: Nghỉ bù | R8: formula | S8: Compute from formula | U8: PERSONAL_DED_AMT | V8: 15500000 | W8: Giảm trừ bản thân/tháng (nhánh chính thức; thử việc cần HR xác nhận)
A9: REGIME_DAYS | C9: =SUBSTITUTE(ADDRESS(1, MATCH(A9, 'Payroll Mar 2026'!$8:$8, 0), 4), "1", "") -> #N/A | D9: 140 | E9: input | G9: WD API | H9: Nghỉ chế độ & có hưởng lương | R9: system | S9: what does this mean? | U9: DEPENDENT_DED | V9: 6200000 | W9: Giảm trừ mỗi người phụ thuộc/tháng
A10: UNPAID_DAYS | B10: TIME_TRACKING | C10: =SUBSTITUTE(ADDRESS(1, MATCH(A10, 'Payroll Mar 2026'!$8:$8, 0), 4), "1", "") -> AE | D10: 145 | E10: input | G10: WD API | H10: Nghỉ không hưởng lương | Q10: tax | R10: TRUE | S10: Include tax | U10: UNION_FEE_RATE | V10: 0.005 | W10: Đoàn phí công đoàn NLĐ (0.5%)
A11: SI_DAYS | B11: TIME_TRACKING | C11: =SUBSTITUTE(ADDRESS(1, MATCH(A11, 'Payroll Mar 2026'!$8:$8, 0), 4), "1", "") -> AF | D11: 150 | E11: input | G11: WD API | H11: Nghỉ chế độ BHXH | R11: FALSE | S11: No-include tax | U11: UNION_FEE_MAX | V11: 253000 | W11: Trần đoàn phí công đoàn NLĐ/tháng
A12: ADJ_DAYS | B12: TIME_TRACKING | C12: =SUBSTITUTE(ADDRESS(1, MATCH(A12, 'Payroll Mar 2026'!$8:$8, 0), 4), "1", "") -> AG | D12: 155 | E12: input | G12: WD API | H12: Ngày công điều chỉnh | Q12: vis | R12: #N/A | S12: Hide in Payslip | U12: SI_EMP_RATE | V12: 0.08 | W12: BHXH người lao động (8%)
A13: CONS_ALLOW | C13: =SUBSTITUTE(ADDRESS(1, MATCH(A13, 'Payroll Mar 2026'!$8:$8, 0), 4), "1", "") -> #N/A | D13: 158 | E13: input | H13: Phụ cấp công trình | R13: other | S13: Show in Payslip | U13: HI_EMP_RATE | V13: 0.015 | W13: BHYT người lao động (1.5%)
A14: PAID_DAYS | B14: TIME_TRACKING_TOTAL | C14: =SUBSTITUTE(ADDRESS(1, MATCH(A14, 'Payroll Mar 2026'!$8:$8, 0), 4), "1", "") -> AI | D14: 190 | E14: formula | H14: Tổng ngày làm việc hưởng lương | I14: [ACTUAL_DAYS] + [HOLIDAY_DAYS] + [PAID_LEAVE_DAYS] + [COMP_DAYS] + [REGIME_DAYS] + [SI_DAYS] + [ADJ_DAYS] | J14: IF([CONTRACT_TYPE]="Chính thức", [OFFICIAL_DAYS], [PROB_DAYS]) + [HOLIDAY_DAYS] + [PAID_LEAVE_DAYS] + [COMP_DAYS] + [REGIME_DAYS] + [SI_DAYS] + [ADJ_DAYS] | K14: IF(Loại hợp đồng="Chính thức") : Ngày làm việc thực tế-Sau thử việc + Nghỉ phép năm + Nghỉ lễ, tết + Nghỉ bù + Nghỉ có hưởng lương + Nghỉ chế độ (ma chay, hiếu hỉ); ELSE: Ngày làm việc thực tế-Thử việc + Nghỉ phép năm + Nghỉ lễ, tết + Nghỉ bù + Nghỉ có hưởng lương + Nghỉ chế độ (ma chay, hiếu hỉ)) (nguồn: AI9) | L14: K phân 2 nhánh HĐ: Chính thức dùng "Ngày thực tế SAU thử việc"; Thử việc dùng "Ngày thực tế THỬ VIỆC". J gộp 1 CT + dư SI_DAYS/ADJ_DAYS → cần tách 2 nhánh. | M14: N | Q14: editable | R14: TRUE | S14: Allow edit after compute | U14: UI_EMP_RATE | V14: 0.01 | W14: BHTN người lao động (1%)
A15: PROB_SAL | B15: SAL_CONTRACT_BASE | C15: =SUBSTITUTE(ADDRESS(1, MATCH(A15, 'Payroll Mar 2026'!$8:$8, 0), 4), "1", "") -> Q | E15: input | G15: WD | H15: Lương thử việc (85%) | R15: FALSE | S15: Can not edit | U15: SI_ER_RATE | V15: 0.17 | W15: BHXH doanh nghiệp (17%)
A16: BASIC_SAL | B16: SAL_CONTRACT_BASE | C16: =SUBSTITUTE(ADDRESS(1, MATCH(A16, 'Payroll Mar 2026'!$8:$8, 0), 4), "1", "") -> R | D16: 200 | E16: input | G16: WD | H16: Lương chính thức (100%) | U16: TNLD_ER_RATE | V16: 0.005 | W16: BH TNLĐ-BNN doanh nghiệp (0.5%)
A17: RESP_SAL | B17: SAL_CONTRACT_BASE | C17: =SUBSTITUTE(ADDRESS(1, MATCH(A17, 'Payroll Mar 2026'!$8:$8, 0), 4), "1", "") -> S | D17: 210 | E17: input | G17: WD API - CTD Payroll | H17: Phụ cấp trách nhiệm | U17: HI_ER_RATE | V17: 0.03 | W17: BHYT doanh nghiệp (3%)
A18: CONTRACT_TOTAL | B18: SAL_CONTRACT_BASE_TOTAL | C18: =SUBSTITUTE(ADDRESS(1, MATCH(A18, 'Payroll Mar 2026'!$8:$8, 0), 4), "1", "") -> T | D18: 220 | E18: formula | H18: Tổng lương trên HĐLĐ | I18: [BASIC_SAL] + [RESPONSIBILITY_ALLOW] | J18: IF([CONTRACT_TYPE]="Chính thức", [BASIC_SAL] + [RESP_SAL], [PROB_SAL]) | K18: IF(Loại hợp đồng="Chính thức": Chính thức (100%) + Phụ cấp Trách nhiệm; ELSE: Thử việc (85%)) (nguồn: T9) | L18: 2 CT: Chính thức = BASIC_SAL(100%) + RESPONSIBILITY_ALLOW; Thử việc = PROB_SAL(85%). J chỉ có nhánh chính thức. | M18: N | U18: UI_ER_RATE | V18: 0.01 | W18: BHTN doanh nghiệp (1%)
A19: INS_SAL_BH | C19: =SUBSTITUTE(ADDRESS(1, MATCH(A19, 'Payroll Mar 2026'!$8:$8, 0), 4), "1", "") -> U | D19: 300 | E19: formula | H19: Mức lương đóng BHXH, BHYT | I19: MIN([BASIC_SAL], 50600000) | J19: IF(AND([CONTRACT_TYPE]="Chính thức", [HAS_SECOND_CONTRACT]=FALSE), MIN([BASIC_SAL], [SI_CAP]), 0) | K19: IF(Loại hợp đồng="Chính thức": MIN(Tổng lương trên HĐLĐ, 50.600.000); else = 0) (nguồn: U9) Nhân viên có hợp đồng 2 nơi, thì k đóng BHXH, BHYT | L19: 2 CT: Chính thức = MIN(BASIC_SAL, 50.600.000); Thử việc = 0. LOẠI TRỪ: NV có HĐ 2 nơi → 0 (K row19). Người nước ngoài VẪN đóng BHXH/BHYT. | M19: N | Q19: Lưu ý th HĐ 2 nơi đang k đc quản lý trên WD, cần lưu master data | U19: KPCD_RATE | V19: 0.02 | W19: Kinh phí công đoàn doanh nghiệp (2%)
A20: INS_SAL_UI | C20: =SUBSTITUTE(ADDRESS(1, MATCH(A20, 'Payroll Mar 2026'!$8:$8, 0), 4), "1", "") -> V | D20: 310 | E20: formula | H20: Mức lương đóng BHTN | I20: MIN([BASIC_SAL], 106200000) | J20: IF(AND([CONTRACT_TYPE]="Chính thức", [IS_FOREIGNER]=FALSE, [HAS_SECOND_CONTRACT]=FALSE), MIN([BASIC_SAL], [UI_CAP]), 0) | K20: IF(Loại hợp đồng="Chính thức": MIN(Tổng lương trên HĐLĐ, 106.200.000); expath = 0; ELSE: 0) (nguồn: V9) Nhân viên có hđ 2 nơi thì k đóng BHTN | L20: BHTN: Chính thức = MIN(BASIC_SAL, 106.200.000); Thử việc = 0. LOẠI TRỪ: người nước ngoài = 0 (expat không đóng BHTN) VÀ NV có HĐ 2 nơi = 0 (K row20). | M20: N | U20: HAS_TERMINATION | V20: (input) | W20: Cờ chấm dứt HĐ trong kỳ (TRUE/FALSE) — chặn trích trước thưởng
A21: PROB_EARNED | B21: SAL_ACTUAL | C21: =SUBSTITUTE(ADDRESS(1, MATCH(A21, 'Payroll Mar 2026'!$8:$8, 0), 4), "1", "") -> AJ | D21: 400 | E21: formula | H21: Lương thử việc | I21: [PROB_DAYS] * [PROB_SAL] / [STD_DAYS] | J21: IF([CONTRACT_TYPE]="Thử việc", ROUND([PROB_SAL] / [STD_DAYS] * [PAID_DAYS], 0), 0) | K21: IF(Loại hợp đồng="Thử việc": ROUND(Thử việc (85%) / CÔNG CHUẨN × Tổng số ngày làm việc hưởng lương); ELSE: 0) (nguồn: AJ9) | L21: 2 CT: Thử việc = ROUND(PROB_SAL/STD_DAYS × PAID_DAYS); Chính thức = 0. J thiếu ROUND + thiếu nhánh =0. | M21: Y | Q21: general check: rounding method | U21: PAID_LEAVE_BALANCE_DAYS | V21: (input) | W21: Số ngày phép tồn — tính lương phép tồn (r25)
A22: OFFICIAL_EARNED | B22: SAL_ACTUAL | C22: =SUBSTITUTE(ADDRESS(1, MATCH(A22, 'Payroll Mar 2026'!$8:$8, 0), 4), "1", "") -> AK | D22: 410 | E22: formula | H22: Lương chính thức | I22: ([PAID_DAYS] - [PROB_DAYS]) * [BASIC_SAL] / [STD_DAYS] | J22: IF([CONTRACT_TYPE]="Chính thức", ROUND([BASIC_SAL] / [STD_DAYS] * [PAID_DAYS], 0), 0) | K22: IF(Loại hợp đồng="Chính thức": ROUND(Chính thức (100%) / CÔNG CHUẨN × Tổng số ngày làm việc hưởng lương); ELSE: 0) (nguồn: AK9) | L22: 2 CT: Chính thức = ROUND(BASIC_SAL/STD_DAYS × PAID_DAYS); Thử việc = 0. J thiếu ROUND. | M22: Y | Q22: TIỀN: XX.00 | U22: BONUS_SAVE_TRAVEL_AMT | V22: 10000000 | W22: Mức thưởng du lịch/năm để trích trước (r119 = /12)
A23: RESP_EARNED | B23: SAL_ACTUAL | C23: =SUBSTITUTE(ADDRESS(1, MATCH(A23, 'Payroll Mar 2026'!$8:$8, 0), 4), "1", "") -> AL | D23: 420 | E23: formula | H23: Phụ cấp trách nhiệm (thực tế) | I23: [PAID_DAYS] * [RESPONSIBILITY_ALLOW] / [STD_DAYS] | J23: ROUND([PAID_DAYS] * [RESP_SAL] / [STD_DAYS], 0) | K23: ROUND(Phụ cấp Trách nhiệm / CÔNG CHUẨN × Tổng số ngày làm việc hưởng lương) (nguồn: AL9) | M23: Y | Q23: day/other: xx.5, yy.0 | U23: BONUS_SAVE_TET_CAP | V23: 15000000 | W23: Trần lương tháng 13/Tết để trích trước (r125)
A24: EARNED_SAL | B24: SAL_ACTUAL_TOTAL | C24: =SUBSTITUTE(ADDRESS(1, MATCH(A24, 'Payroll Mar 2026'!$8:$8, 0), 4), "1", "") -> AN | D24: 490 | E24: formula | H24: Tổng lương thực tế trong tháng | I24: [PROB_EARNED] + [OFFICIAL_EARNED] + [RESP_EARNED] | J24: ROUND([PROB_EARNED] + [OFFICIAL_EARNED] + [RESP_EARNED] + [EARNED_PAID_LEAVE], 0) | K24: ROUND(Lương Thử việc + Lương chính thức + Phụ cấp Trách nhiệm + Lương phép tồn) (nguồn: AN9 — lưu ý: có cộng thêm "Lương phép tồn", công thức Structure không có mục này) | L24: K = ROUND(PROB_EARNED + OFFICIAL_EARNED + RESP_EARNED + [EARNED_PAID_LEAVE]). J THIẾU "Lương phép tồn" (r25) + thiếu ROUND. | Q24: số phép tồn x mức lương (R16) / stand_d, áp dụng cho nhân viên chính thức | U24: IS_EXPAT_NO_WP | V24: (input) | W24: TRUE nếu người nước ngoài KHÔNG có work permit → PIT = 20% × TNTT
A25: EARNED_PAID_LEAVE | C25: =SUBSTITUTE(ADDRESS(1, MATCH(A25, 'Payroll Mar 2026'!$8:$8, 0), 4), "1", "") -> AM | E25: formula | H25: Lương phép tồn | J25: IF([CONTRACT_TYPE]="Chính thức", ROUND([PAID_LEAVE_BALANCE_DAYS] / [STD_DAYS] * [BASIC_SAL], 0), 0) | K25: =ngày phép tồn/ngày công chuẩn * Mức lương, chỉ áp dụng cho nhân viên chính thức | L25: K: ngày phép tồn / công chuẩn × mức lương, CHỈ NV chính thức. Cần biến [PAID_LEAVE_BALANCE_DAYS] (input). | U25: EMP_TYPE | V25: (input) | W25: Loại NV: "Intern"/"Chính thức"… — chọn nhánh tính PIT
A26: MEALS_BASE | C26: =SUBSTITUTE(ADDRESS(1, MATCH(A26, 'Payroll Mar 2026'!$8:$8, 0), 4), "1", "") -> #N/A | D26: 500 | E26: input | G26: excel compute | H26: Cơm phụ cấp (bữa) | K26: WD không trả cơm bữa, đếm số cơm bữa bằng cách cộng tổng ngày có Regular time tracking = 1 | L26: K: WD không trả cơm bữa — đếm bằng tổng ngày Regular time tracking=1. Dạng input dẫn xuất từ WD. | Q26: WD trả cơm đêm + cơm tăng ca, k trả cơm hằng ngày. cơm hằng ngày lấy theo Regular =1 | U26: HAS_TAX_COMMITMENT | V26: (input) | W26: Intern có giấy cam kết thuế (TRUE) → PIT = 0
A27: MEALS_OT | C27: =SUBSTITUTE(ADDRESS(1, MATCH(A27, 'Payroll Mar 2026'!$8:$8, 0), 4), "1", "") -> #N/A | D27: 501 | E27: input | G27: WD API - CTD Payroll | H27: Cơm tăng ca (bữa) | K27: WD có trả cơm tăng ca, lấy từ WD | L27: K: cơm tăng ca lấy trực tiếp từ WD. Input. | Q27: = cơm đêm + cơm CN + tăng ca lễ | U27: IS_FOREIGNER | V27: (input) | W27: TRUE nếu người nước ngoài → không đóng BHTN (r20)
A28: MEALS_TOTAL | C28: =SUBSTITUTE(ADDRESS(1, MATCH(A28, 'Payroll Mar 2026'!$8:$8, 0), 4), "1", "") -> #N/A | D28: 502 | E28: formula | H28: Tổng bữa cơm | U28: HAS_SECOND_CONTRACT | V28: (input) | W28: TRUE nếu có HĐLĐ ở nơi khác → không đóng BHXH/BHYT/BHTN (r19,20)
A29: MEAL_ALLOW | C29: =SUBSTITUTE(ADDRESS(1, MATCH(A29, 'Payroll Mar 2026'!$8:$8, 0), 4), "1", "") -> #N/A | D29: 505 | E29: formula | H29: PC cơm (tổng) | I29: [MEALS_TOTAL] * 45000 | J29: [MEALS_TOTAL] * [MEAL_RATE] | K29: Không có công thức trong sample - "PC cơm (Taxable)" và "PC cơm (Non-tax)" được nhập trực tiếp (Input) | L29: K coi PC cơm = NHẬP TAY (input). J dẫn xuất MEALS_TOTAL×45000 → xác nhận WD có trả cơm bữa hay nhập tay.
A30: MEAL_TAX | B30: PC_TAX | C30: =SUBSTITUTE(ADDRESS(1, MATCH(A30, 'Payroll Mar 2026'!$8:$8, 0), 4), "1", "") -> AO | D30: 510 | E30: formula | F30: T | H30: PC cơm (chịu thuế) | I30: MAX(0, [MEAL_ALLOW] - 1200000) | J30: MAX(0, [MEAL_ALLOW] - [MEAL_NONTAX_CAP]) | K30: Không có công thức trong sample - "PC cơm (Taxable)" được nhập trực tiếp (Input), không tính từ tổng bữa ăn | L30: K: PC cơm(Taxable) nhập tay, không tính từ tổng bữa. J dùng MAX(0, MEAL_ALLOW-1.200.000). | Q30: tổng phụ cơm > 1tr2 thì phần chênh lệch là chịu thuế
A31: PHONE_ALLOW | B31: PC_TAX | C31: =SUBSTITUTE(ADDRESS(1, MATCH(A31, 'Payroll Mar 2026'!$8:$8, 0), 4), "1", "") -> AP | D31: 520 | E31: input | G31: WD API - CTD Payroll | H31: PC điện thoại (tổng)
A32: PHONE_TAX | B32: PC_TAX | C32: =SUBSTITUTE(ADDRESS(1, MATCH(A32, 'Payroll Mar 2026'!$8:$8, 0), 4), "1", "") -> #N/A | D32: 525 | E32: formula | F32: T | H32: PC điện thoại (chịu thuế) | I32: 0 | K32: Không có công thức trong sample - "PC điện thoại (Taxable)" được nhập trực tiếp (Input)
A33: FUEL_ALLOW | B33: PC_TAX | C33: =SUBSTITUTE(ADDRESS(1, MATCH(A33, 'Payroll Mar 2026'!$8:$8, 0), 4), "1", "") -> AQ | D33: 530 | E33: input | F33: T | G33: WD API - CTD Payroll | H33: PC NL/ Xăng
A34: TRANSPORT_ALLOW | C34: =SUBSTITUTE(ADDRESS(1, MATCH(A34, 'Payroll Mar 2026'!$8:$8, 0), 4), "1", "") -> #N/A | D34: 535 | E34: input | G34: WD API - CTD Payroll | H34: PC đi lại (chuẩn)
A35: TRIP_OVERRIDE | C35: =SUBSTITUTE(ADDRESS(1, MATCH(A35, 'Payroll Mar 2026'!$8:$8, 0), 4), "1", "") -> #N/A | D35: 537 | E35: input | G35: HR input | H35: PC đi lại duyệt riêng
A36: TRANSPORT_TAX | B36: PC_TAX | C36: =SUBSTITUTE(ADDRESS(1, MATCH(A36, 'Payroll Mar 2026'!$8:$8, 0), 4), "1", "") -> AR | D36: 540 | E36: formula | F36: T | H36: PC đi lại (chịu thuế) | I36: [TRANSPORT_ALLOW] + [TRIP_OVERRIDE] | J36: [TRANSPORT_ALLOW] + [TRIP_OVERRIDE] | K36: Không có công thức trong sample - "PC đi lại (Taxable)" được nhập trực tiếp (Input) | Q36: ưu tiên PC override nếu có
A37: LIVING_ALLOW | B37: PC_TAX | C37: =SUBSTITUTE(ADDRESS(1, MATCH(A37, 'Payroll Mar 2026'!$8:$8, 0), 4), "1", "") -> AS | D37: 545 | E37: input | F37: T | G37: HR input | H37: PC nhà ở
A38: OTHER_ALLOW_TAX | B38: PC_TAX | C38: =SUBSTITUTE(ADDRESS(1, MATCH(A38, 'Payroll Mar 2026'!$8:$8, 0), 4), "1", "") -> AT | D38: 550 | E38: input | F38: T | G38: HR input | H38: PC Khác (chịu thuế)
A39: MEAL_NONTAX | B39: PC_NOTAX | C39: =SUBSTITUTE(ADDRESS(1, MATCH(A39, 'Payroll Mar 2026'!$8:$8, 0), 4), "1", "") -> AU | D39: 600 | E39: formula | H39: PC cơm (không chịu thuế) | I39: MIN([MEAL_ALLOW], 1200000) | J39: MIN([MEAL_ALLOW], [MEAL_NONTAX_CAP]) | K39: Không có công thức trong sample - "PC cơm (Non-tax)" được nhập trực tiếp (Input) | L39: K: PC cơm(Non-tax) nhập tay. J dùng MIN(MEAL_ALLOW, 1.200.000).
A40: PHONE_NONTAX | B40: PC_NOTAX | C40: =SUBSTITUTE(ADDRESS(1, MATCH(A40, 'Payroll Mar 2026'!$8:$8, 0), 4), "1", "") -> AV | D40: 605 | E40: formula | H40: PC điện thoại (không chịu thuế) | I40: [PHONE_ALLOW | J40: [PHONE_ALLOW] | K40: Không có công thức trong sample - "PC điện thoại (Non-tax)" được nhập trực tiếp (Input) | L40: CT J VỠ: "[PHONE_ALLOW" thiếu "]". K: nhập tay. Sửa = [PHONE_ALLOW] hoặc để input.
...

Sheet Payroll Mar 2026
E1: Công chuẩn VP | F1: =NETWORKDAYS.INTL(H1,H2,1)+NETWORKDAYS.INTL(H1,H2,"1111101")/2 -> #VALUE! | G1: Ngày bắt đầu | H1: DD/MM/YYYY
E2: Công chuẩn CT | F2: =NETWORKDAYS.INTL(H1,H2,11) -> #VALUE! | G2: Ngày kết thúc | H2: DD/MM/YYYY | U2: =U9 * 0.17 -> 8602000
A3: CTD BẢNG LƯƠNG THÁNG MM/YYYY | AO3: =AO4+AU4 -> -990000 | AP3: =AP4+AV4 -> 1000000 | CO3: =-CO4+CW4 -> -21049361 | CY3: =CX4+CY4 -> 0 | DA3: =DB4-CZ4 -> 0 | DL3: =DL4+CE4 -> 16164000 | EV3: Điều chỉnh lương bổ nhiệm chính thức
Q4: =SUBTOTAL(9,Q9:Q9) -> 0 | R4: =SUBTOTAL(9,R9:R9) -> 200000000 | S4: =SUBTOTAL(9,S9:S9) -> 0 | T4: =SUBTOTAL(9,T9:T9) -> 200000000 | U4: =SUBTOTAL(9,U9:U9) -> 50600000 | V4: =SUBTOTAL(9,V9:V9) -> 106200000 | W4: =SUBTOTAL(9,W9:W9) -> 22 | X4: =SUBTOTAL(9,X9:X9) -> 0 | ... DZ4: =SUBTOTAL(9,DZ9:DZ9) -> 0 | EE4: =SUBTOTAL(9,EE9:EE9) -> 305018667 | EF4: =SUBTOTAL(9,EF9:EF9) -> 0 | EI4: =SUBTOTAL(9,EI9:EI9) -> 3 | EV4: Add PC trách nhiệm Quyền
A5: STT | B5: STT (theo phòng ban) | C5: VP/CT | D5: MÃ KIỂM TOÁN | E5: MÃ SỐ NHÂN VIÊN | F5: TÊN NHÂN VIÊN | G5: Quốc tịch | H5: MÃ WSB PHÒNG BAN BỔ CHI PHÍ | I5: TÊN PHÒNG BAN BỔ CHI PHÍ | J5: BỘ PHẬN | K5: CHỨC DANH | L5: NGẠCH - BẬC | M5: LOẠI HỢP ĐỒNG | N5: NGÀY VÀO LÀM | O5: NGÀY KẾT THÚC THỬ VIỆC | P5: NGÀY NGHỈ VIỆC | Q5: MỨC LƯƠNG HỢP ĐỒNG | U5: MỨC LƯƠNG ĐÓNG BHXH, BHYT | V5: MỨC LƯƠNG ĐÓNG BHTN | W5: CÔNG CHUẨN | X5: CÁC NGÀY CÔNG TRONG THÁNG | AJ5: LƯƠNG THỰC TẾ | AO5: PHỤ CẤP TÍNH THUẾ | AU5: PHỤ CẤP KHÔNG TÍNH THUẾ | BA5: TĂNG CA | BC5: CÁC LOẠI THƯỞNG | BN5: KHOẢN THU NHẬP KHÁC NGOÀI LƯƠNG | BP5: CÁC LOẠI TRỢ CẤP KHÁC | BS5: CÁC KHOẢN HỖ TRỢ Chi phí BHSK công ty tài trợ | BT5: ĐIỀU CHỈNH TRƯỚC THUẾ | BV5: TỪ THIỆN | BW5: TỔNG THU NHẬP TRONG THÁNG | BX5: TỔNG THU NHẬP CHỊU THUẾ | BY5: BHXH TRÍCH ĐÓNG NHÂN VIÊN | CF5: GIẢM TRỪ GIA CẢNH | CJ5: THU NHẬP TÍNH THUẾ | CK5: THUẾ TNCN | CL5: ĐIỀU CHỈNH THUẾ TNCN | CM5: TỔNG THUẾ TNCN ĐÃ KHẤU TRỪ | CN5: THU NHẬP THUẦN | CO5: CÁC KHOẢN CỘNG SAU THUẾ | CT5: CÁC KHOẢN TRỪ SAU THUẾ | CZ5: LƯƠNG THỰC NHẬN | DB5: LƯƠNG THỰC CHI | DD5: CHI PHÍ CÔNG TY | DO5: MST | DP5: THU NHẬP THÁNG | DQ5: TRÍCH THƯỞNG HÀNG THÁNG | DZ5: Nhóm chức danh | EA5: Profits Center | EB5: Cost Center | EC5: WBS | ED5: Funds Center | EE5: Check budget | EO5: Phụ cấp trách nhiệm bổ sung (Back date)
Q6: Lương thử việc | R6: Lương chính thức | S6: Phụ cấp Trách nhiệm | T6: Tổng lương trên HĐLĐ | X6: Ngày làm việc thực tế -Thử việc | Y6: Ngày làm việc thực tế-Sau thử việc | Z6: Nghỉ phép năm | AA6: Ngày nghỉ lễ, tết | AB6: Ngày nghỉ bù | AC6: Nghỉ có hưởng lương | AD6: Ngày nghỉ chế độ (ma chay, hiếu hỉ) | AE6: Ngày nghỉ không lương | AF6: Ngày chế độ BHXH | AG6: Ngày công bổ sung | AH6: Ngày phép tồn | AI6: Tổng số ngày làm việc hưởng lương | AJ6: Lương Thử việc | AK6: Lương chính thức | AL6: Phụ cấp Trách nhiệm | AM6: Lương phép tồn | AN6: Tổng lương thực tế trong tháng | AO6: Phụ cấp cơm | AP6: Phụ cấp điện thoại | AQ6: Phụ cấp NL/ Xăng | AR6: Phụ cấp đi lại | AS6: Phụ cấp nhà ở | AT6: Phụ cấp khác | AU6: Phụ cấp cơm | AV6: Phụ cấp điện thoại | AW6: Phụ cấp NL/ Xăng | AX6: Phụ cấp đi lại | AY6: Phụ cấp nhà ở | AZ6: Phụ cấp khác | BA6: CHỊU THUẾ | BB6: KHÔNG CHỊU THUẾ | BC6: TẾT ÂM LỊCH | BD6: THƯỞNG 30/04 | BE6: COTECCONS DAY | BF6: THƯỞNG 02/09 | BG6: THƯỞNG VĂN PHÒNG/KPIs | BH6: LƯƠNG THÁNG 13 | BI6: TẾT DƯƠNG LỊCH | BJ6: THƯỞNG DỰ ÁN | BK6: CÁ NHÂN SUẤT XẮC | BL6: LỘC ĐẦU NĂM | BM6: THƯỞNG KHÁC | BN6: DU LỊCH | BO6: Thưởng giới thiệu ứng viên nội bộ | BP6: TRỢ CẤP NGHỈ VIỆC | BQ6: BHXH chi vào lương | BR6: TRỢ CẤP KHÁC | BT6: ĐIỀU CHỈNH CỘNG | BU6: ĐIỀU CHỈNH TRỪ | BY6: BHXH 8% | BZ6: Đ/C BHXH 8% | CA6: BHYT 1.5% | CB6: Đ/C BHYT 1.5% | CC6: BHTN 1% | CD6: Đ/C BHTN 1% | CE6: Tổng BHXH của NLĐ | CF6: GIẢM TRỪ BẢN THÂN | CG6: SỐ NPT | CH6: GIẢM TRỪ GIA CẢNH | CI6: TỔNG KHOẢN GIẢM TRỪ | CO6: HOÀN QUYẾT TOÁN THUẾ | CP6: CHẾ ĐỘ BHXH | CQ6: TRỢ CẤP THÔI VIỆC (Trích quỹ) | CR6: TRỢ CẤP THÔI VIỆC NĐ 145/2020 | CS6: CÁC KHOẢN CỘNG SAU THUẾ KHÁC | CT6: PHÍ CÔNG ĐOÀN 0.5% | CU6: THU HỘ BẢO HIỂM BẢO VIỆT | CV6: TRỪ LỘC ĐẦU NĂM | CW6: QUYẾT TOÁN THUẾ | CX6: Các khoản trừ sau thuế khác (Phí bồi hoàn khóa đào tạo, cá nhân xuất sắc) | CY6: Các khoản trừ sau thuế khác (BHSK ng thân cty tài trợ) | CZ6: VND | DA6: USD | DB6: VND | DC6: GHI CHÚ | DD6: BHXH 17% | DE6: Đ/C BHXH 17% | DF6: BHTNLĐ-BNN 0,5% | DG6: Đ/C BHTNLĐ-BNN 0,5% | DH6: BHYT 3% | DI6: Đ/C BHYT 3% | DJ6: BHTN 1% | DK6: Đ/C BHTN 1% | DL6: Tổng BHXH Cty đóng | DM6: 2% KPCĐ | DN6: Tổng chi phí công ty | DQ6: Tết dương lịch 1/1 | DR6: 30/4 | DS6: Du lịch | DT6: Coteccons day | DU6: 2/9 | DV6: Bổ sung đợt 2 | DW6: Thưởng KPIs | DX6: Lương tháng 13 | DY6: Thưởng Âm lịch | EF6: Check | EG6: Check headcount bảng công | EH6: Giới tính (để báo cáo) | EI6: NPT 01/2026 | EJ6: OFF-BOARDING | EK6: Ghi chú tuyển dụng/ luân chuyển | EL6: Email NV mới gửi Payslip | EM6: Nhận thưởng QS Retention 12/2025 | EN6: Ngày hiệu lực thêm PC trách nhiệm | EO6: Ghi chú hiệu lực PC trách nhiệm | EP6: Ngày hiệu lực ĐCL lương | EQ6: Điều chỉnh lương CÔNG TY | ER6: Lương trước điều chỉnh | ES6: PC trách nhiệm trước điều chỉnh | ET6: % điều chỉnh lương | EU6: Điều chỉnh lương trong tháng | EV6: Ghi chú điều chỉnh/bổ sung trong tháng | EW6: Công thức tính PIT hàm IF | EX6: Check | EY6: Level Payroll 01/2026 | EZ6: Level sau MYR
Q7: =VLOOKUP(Q8,'Payroll structure'!$A$2:$E$126,5,FALSE) -> input | R7: =VLOOKUP(R8,'Payroll structure'!$A$2:$E$126,5,FALSE) -> input | S7: =VLOOKUP(S8,'Payroll structure'!$A$2:$E$126,5,FALSE) -> input | T7: =VLOOKUP(T8,'Payroll structure'!$A$2:$E$126,5,FALSE) -> formula | U7: =VLOOKUP(U8,'Payroll structure'!$A$2:$E$126,5,FALSE) -> formula | V7: =VLOOKUP(V8,'Payroll structure'!$A$2:$E$126,5,FALSE) -> formula | W7: =VLOOKUP(W8,'Payroll structure'!$A$2:$E$126,5,FALSE) -> input | X7: =VLOOKUP(X8,'Payroll structure'!$A$2:$E$126,5,FALSE) -> input | ... DO7: =VLOOKUP(DO8,'Payroll structure'!$A$2:$E$126,5,FALSE) -> #N/A | DP7: vd kì lương tháng 1 | DQ7: =VLOOKUP(DQ8,'Payroll structure'!$A$2:$E$126,5,FALSE) -> formula | DR7: =VLOOKUP(DR8,'Payroll structure'!$A$2:$E$126,5,FALSE) -> formula | DS7: =VLOOKUP(DS8,'Payroll structure'!$A$2:$E$126,5,FALSE) -> formula | DT7: =VLOOKUP(DT8,'Payroll structure'!$A$2:$E$126,5,FALSE) -> formula | DU7: =VLOOKUP(DU8,'Payroll structure'!$A$2:$E$126,5,FALSE) -> formula | DV7: =VLOOKUP(DV8,'Payroll structure'!$A$2:$E$126,5,FALSE) -> formula | DW7: =VLOOKUP(DW8,'Payroll structure'!$A$2:$E$126,5,FALSE) -> formula | DX7: =VLOOKUP(DX8,'Payroll structure'!$A$2:$E$126,5,FALSE) -> formula | ... EE7: =VLOOKUP(EE8,'Payroll structure'!$A$2:$E$126,5,FALSE) -> formula | EF7: fml | EG7: input | EH7: input | EI7: input | EJ7: input | EK7: input | EL7: input | EM7: input | EN7: input | EO7: input | EP7: input | EQ7: input | ER7: input | ES7: input | ET7: fml
Q8: PROB_SAL | R8: BASIC_SAL | S8: RESP_SAL | T8: CONTRACT_TOTAL | U8: INS_SAL_BH | V8: INS_SAL_UI | W8: STD_DAYS | X8: PROB_DAYS | Y8: OFFICIAL_DAYS | Z8: PAID_LEAVE_DAYS | AA8: HOLIDAY_DAYS | AB8: COMP_DAYS | AE8: UNPAID_DAYS | AF8: SI_DAYS | AG8: ADJ_DAYS | AI8: PAID_DAYS | AJ8: PROB_EARNED | AK8: OFFICIAL_EARNED | AL8: RESP_EARNED | AM8: EARNED_PAID_LEAVE | AN8: EARNED_SAL | AO8: MEAL_TAX | AP8: PHONE_ALLOW | AQ8: FUEL_ALLOW | AR8: TRANSPORT_TAX | AS8: LIVING_ALLOW | AT8: OTHER_ALLOW_TAX | AU8: MEAL_NONTAX | AV8: PHONE_NONTAX | AW8: FUEL_NONTAX | AX8: TRANSPORT_NONTAX | AY8: LIVING_NONTAX | AZ8: OTHER_ALLOW_NONTAX | BA8: OT_TAX | BB8: OT_NONTAX | BC8: BONUS_TET | BD8: BONUS_30_04 | BE8: BONUS_CTD_DAY | BF8: BONUS_02_09 | BG8: BONUS_KPI | BH8: BONUS_13M | BI8: BONUS_NEW_YEAR | BJ8: BONUS_PROJECT | BK8: BONUS_EXCELLENCE | BL8: BONUS_LOC | BM8: BONUS_OTHER | BN8: BONUS_TRAVEL | BO8: BONUS_REFERRAL | BP8: SEVER_ALLOW | BQ8: SI_BENEFIT | BR8: OTHER_SUPPORT | BT8: ADJ_PLUS | BU8: ADJ_MINUS | BV8: CHARITY_DED | BW8: GROSS | BX8: TAXABLE_GROSS | BY8: SI_EMP | BZ8: SI_ADJ | CA8: HI_EMP | CB8: HI_ADJ | CC8: UI_EMP | CD8: UI_ADJ | CE8: TOTAL_INS | CF8: PERSONAL_DED | CG8: DEPENDENT_CNT | CH8: DEPENDENT_DED | CI8: TOTAL_DED | CJ8: TAXABLE_INC | CK8: PIT | CL8: PIT_ADJ | CM8: TOTAL_PIT | CN8: NET_INCOME | CO8: PIT_SETTLE | CP8: SI_REGIME | CQ8: SEVER_FUND | CR8: SEVER_PAY | CS8: OTHER_POST_ADD | CT8: UNION_FEE | CU8: BAOVET_INS | CV8: DEDUCT_LOC | CW8: PIT_SETTLE_DED | CX8: OTHER_POST_DED | CY8: FAMILY_HEALTH_INS | CZ8: NET_PAY | DB8: NET_PAY_HOME | DD8: SI_CTY | DE8: SI_CTY_ADJ | DF8: TNLD_CTY | DG8: TNLD_CTY_ADJ | DH8: HI_CTY | DI8: HI_CTY_ADJ | DJ8: UI_CTY | DK8: UI_CTY_ADJ | DL8: TOTAL_INS_CTY | DM8: KPCD_CTY | DN8: TOTAL_CTY_COST | DQ8: BONUS_SAVE_NEW_YEAR | DR8: BONUS_SAVE_30_04 | DS8: BONUS_SAVE_TRAVEL | DT8: BONUS_SAVE_CTD_DAY | DU8: BONUS_SAVE_02_09 | DV8: BONUS_SAVE_ADD_2 | DW8: BONUS_SAVE_KPI | DX8: BONUS_SAVE_13M | DY8: BONUS_SAVE_TET | EE8: BUDGET_SAVE
A9: =ROW()-ROW($A$7) -> 2 | B9: =SUBTOTAL(3,$F$9:F9) -> 0 | C9: VP301 | M9: Chính thức | N9: 37646 | Q9: 0 | R9: =200*10^6 -> 200000000 | T9: =IF(M9="Chính thức",SUM(R9:S9),Q9) -> 200000000 | U9: =IF(M9="Chính thức",IF(T9>=50600000,50600000,T9),0) -> 50600000 | V9: =IF(M9="Chính thức",IF(T9>=106200000,106200000,T9),0) -> 106200000 | W9: 22 | X9: 0 | Y9: 19.5 | Z9: 0 | AA9: 2.5 | AB9: 0 | AC9: 0 | AD9: 0 | AE9: 0 | AF9: 0 | AG9: 0 | AH9: 0 | AI9: =IF(M9="Chính thức",SUM(Y9:AD9),X9+SUM(Z9:AD9)) -> 22 | AJ9: =IF($M9="Thử việc",IFERROR(ROUND($Q9/$W9*$AI9,0),0),0) -> 0 | AK9: =IF($M9="Chính thức",IFERROR(ROUND($R9/$W9*$AI9,0),0),0) -> 200000000 | AL9: =IFERROR(ROUND(S9/W9*AI9,0),0) -> 0 | AM9: 0 | AN9: =ROUND(SUM(AJ9:AM9),0) -> 200000000 | AO9: 0 | AP9: 0 | AQ9: 25000000 | AR9: 0 | AT9: 0 | AU9: -990000 | AV9: 1000000 | BA9: 0 | BB9: 0 | BC9: 0 | BJ9: 0 | BN9: 0 | BO9: 0 | BP9: 0 | BQ9: 0 | BR9: 0 | BS9: 0 | BT9: 0 | BU9: 0 | BW9: =SUM(AN9:BU9) -> 225010000 | BX9: =SUM(AN9:AT9)+BA9+SUM(BC9:BU9)-BV9-AM9 -> 225000000 | BY9: 3744000 | BZ9: 0 | CA9: 702000 | CB9: 0 | CC9: 1062000 | CD9: 0 | CE9: =IFERROR(SUM(BY9:CD9),0) -> 5508000 | CF9: =IF($M9="Chính thức",15500000,IF($M9="Thử việc",0,0)) -> 15500000 | CG9: 3 | CH9: =CG9*6200000 -> 18600000 | CI9: =CF9+CH9 -> 34100000 | CJ9: =ROUND(IF((BX9-CE9-CI9)<0,0,(BX9-CE9-CI9)),0) -> 185392000 | CK9: {=ROUND(IF(AND(AND($G9="Việt Nam",$M9="Thử việc"),$CJ9>=2000000),$CJ9*10%,IF(AND(AND($G9="Việt Nam",$M9="Thử việc"),$CJ9<2000000),0,IF(AND($G9="Nước ngoài",$M9="Thử việc"),$CJ9*20%,(SUMPRODUCT(($CJ9>{0;10;30;60;100}*10^6)*($CJ9-{0;10;30;60;100}*10^6)*{0.05;0.05;0.1;0.1;0.05}))))),0)} -> 50387200 | CM9: =ROUND(CK9+CL9,0) -> 50387200 | CN9: =ROUND(BW9-CE9-CM9,0) -> 169114800 | CO9: 21049361 | CQ9: 0 | CR9: 0 | CT9: 234000 | CU9: 0 | CV9: =BL9 -> 0 | CW9: 0 | CX9: 0 | CY9: =BS9 -> 0 | CZ9: =ROUND($CN9+SUM($CO9:$CS9)-SUM($CT9:$CY9),0) -> 189930161 | DB9: =ROUND(CZ9,0) -> 189930161 | DD9: 7956000 | DE9: 0 | DF9: 234000 | DG9: 0 | DH9: 1404000 | DI9: 0 | DJ9: 1062000 | DK9: 0 | DL9: =IFERROR(SUM(DD9:DK9),0) -> 10656000 | DM9: 936000 | DN9: =SUM(DL9:DM9)+CZ9 -> 201522161 | DS9: =IF($P9<>"",0,ROUND(6000000/12,0)) -> 500000 | DW9: =IF($P9<>"",0,ROUND($T9/4,0)) -> 50000000 | DX9: =IF($P9<>"",0,ROUND($T9/12,0)) -> 16666667 | DY9: =IF($P9<>"",0,MIN(ROUND($T9/12,0),(ROUND(15000000/12,0)))) -> 1250000 | EE9: =BW9+DL9+DM9+DS9+DW9+DX9+DY9 -> 305018667 | EF9: =SUM(AN9:BV9)-CE9-CM9+SUM(CO9:CS9)-SUM(CT9:CY9)-CZ9 -> 0 | EG9: Bùi Ngọc Kim | EH9: Nam | EI9: 3 | ER9: 182000000 | ES9: 0 | ET9: =ROUND((T9-ER9-ES9)/(ER9+ES9),0) -> 0 | EW9: =ROUND(IF(AND(AND($G9="Việt Nam",$M9="Thử việc"),$CJ9>=2000000),$CJ9*10%,IF(AND(AND($G9="Việt Nam",$M9="Thử việc"),$CJ9<2000000),0,IF(AND($G9="Nước ngoài",$M9="Thử việc"),$CJ9*20%,IF($CJ9<=10000000, $CJ9*5%, IF($CJ9<=30000000, $CJ9*10%-500000, IF($CJ9<=60000000, $CJ9*20%-3500000, IF($CJ9<=100000000, $CJ9*30%-9500000, $CJ9*35%-14500000))))))),0) -> 50387200 | EX9: =EW9=CK9 -> TRUE | EY9: Level 8 | EZ9: Level 8 | FA9: =AG9+AH9 -> 0
U10: Mức trần 50,600,000 | V10: Mức trần 106,200,000 | X10: đếm ngày TV | Y10: đếm ngày chính thức | AJ10: = ngày thử việc* lương thử việc (bao gồm ngày đi làm + ngày nghỉ hưởng lương của Tgian thử việc) | AK10: = ngày chính thức* lương chính thức (bao gồm ngày đi làm + ngày nghỉ hưởng lương của Tgian CThuc) Bổ nhiệm: nếu có 2 mức lương khác nhau trong kỳ lương thì tính theo 2 gdoan | AL10: =ngày hưởng phụ cấp * Định mức phụ cấp/ngày công chuẩn | AM10: =ngày phép tồn/ngày công chuẩn * Mức lương | AN10: =lương thử việc+lương chính thức+phụ cấp trách nhiệm+lương phép tồn (lưu ý cho nhân sự bổ nhiệm có 2 mức lương) | AO10: sau khi tính phụ cấp cơm theo rule: vp: 1b/ngày, site <30km: 2b/ngày, site >=30km: 3b/ngày --> Phụ cấp cơm còn lại sau khi trừ mức miễn 730k -- lưu ý nhân sự điều động | AQ10: VP: up duyệt riêng theo tờ trình CT: L2-L6: 1tr/tháng, lưu ý số ngày đi làm thực tế dưới 14 (mười bốn) ngày, phụ cấp được tính theo tỷ lệ ngày làm việc thực tế và ngày nghỉ lễ trong tháng -- lưu ý nhân sự điều động | AR10: Theo quy định, lưu ý số ngày đi làm thực tế dưới 14 (mười bốn) ngày, phụ cấp được tính theo tỷ lệ ngày làm việc thực tế và ngày nghỉ lễ trong tháng -- lưu ý nhân sự điều động | AT10: Phụ cấp duyệt riêng theo tờ trình | AU10: sau khi tính phụ cấp cơm theo rule: vp: 1b/ngày, site <30km: 2b/ngày, site >=30km: 3b/ngày --> Phụ cấp cơm <=730k, lấy pc cơm thực tế, ngược lại 730k -- lưu ý nhân sự điều động | AV10: Theo level, lưu ý số ngày đi làm thực tế dưới 14 (mười bốn) ngày, phụ cấp được tính theo tỷ lệ ngày làm việc thực tế và ngày nghỉ lễ trong tháng -- lưu ý nhân sự điều động | AX10: Tính theo quy định, lưu ý số ngày đi làm thực tế dưới 14 (mười bốn) ngày, phụ cấp được tính theo tỷ lệ ngày làm việc thực tế và ngày nghỉ lễ trong tháng -- lưu ý nhân sự điều động | BB10: chủ nhật 200% Ngày nghỉ Lễ, Tết theo quy định của pháp luật: theo list DS: trả thêm 100% tiền lương và ghi nhận 2 ngày nghỉ bù cho mỗi ngày đi làm Ngày truyền thống, bổ sung, bù: = và ghi nhận nghỉ bù cho mỗi ngày đi làm | BC10: Lương bình quân 12 tháng liền kề, ko quá 15 triệu Mức hưởng = thời gian tính thưởng/365 * định mức | BH10: Lương bình quân 12 tháng liền kề Mức hưởng = thời gian tính thưởng/365 * định mức | BW10: cộng hết thu nhập | BX10: cộng hết thu nhập chịu thuế | BY10: =8%* lương bhxh --NS chính thức số ngày thử việc, ko lương, thai sản ...>=14 ngày tính từ 1- cuối tháng --ko đóng bhxh | CB10: =1.5%* lương bhxh --NS chính thức | CC10: =1%* lương BHTN --NS chính thức | CH10: Bản thân: 15.5 tr NPT: 6.2 tr/người | CK10: Thử việc: VN 10% * tổng TN NNN 20% * tổng TN Chính thức: theo thu nhập chịu thuế * biểu lũy tiến | CT10: =0.5%* lương bhxh, tối đa 234k --NS chính thức | DD10: =17%* lương bhxh --NS chính thức | DF10: =0.5%* lương bhxh --NS chính thức | DH10: =1%* lương BHTN --NS chính thức | DI10: =3%* lương bhxh --NS chính thức | DJ10: =1%* lương BHTN --NS chính thức | DM10: =2%* lương bhxh --NS chính thức | DS10: Ngày hưởng lương>0, 6tr : 12 | DW10: Ngày hưởng lương>0, lương HĐLD/Lương TV * 3 : 12 | DX10: Ngày hưởng lương>0, lương HĐLD/Lương TV : 12 | DY10: Ngày hưởng lương>0, nếu lương HĐLD/Lương TV>15tr, 15tr: 12, lương HĐLD/Lương TV :12
A11: =IF(A7="formula",VLOOKUP(A8,'Payroll structure'!$A$2:$K$126,11,FALSE), "") | B11: =IF(B7="formula",VLOOKUP(B8,'Payroll structure'!$A$2:$K$126,11,FALSE), "") | C11: =IF(C7="formula",VLOOKUP(C8,'Payroll structure'!$A$2:$K$126,11,FALSE), "") | D11: =IF(D7="formula",VLOOKUP(D8,'Payroll structure'!$A$2:$K$126,11,FALSE), "") | E11: =IF(E7="formula",VLOOKUP(E8,'Payroll structure'!$A$2:$K$126,11,FALSE), "") | F11: =IF(F7="formula",VLOOKUP(F8,'Payroll structure'!$A$2:$K$126,11,FALSE), "") | G11: =IF(G7="formula",VLOOKUP(G8,'Payroll structure'!$A$2:$K$126,11,FALSE), "") | H11: =IF(H7="formula",VLOOKUP(H8,'Payroll structure'!$A$2:$K$126,11,FALSE), "") | ... EE11: =IF(EE7="formula",VLOOKUP(EE8,'Payroll structure'!$A$2:$K$126,11,FALSE), "") -> =[TOTAL_CTY_COST] + [BONUS_SAVE_TRAVEL] + [BONUS_SAVE_KPI] + [BONUS_SAVE_13M] + [BONUS_SAVE_TET]
C143: ,35,0

Sheet Payslip template
A1: ="PHIẾU LƯƠNG THÁNG "&TEXT(J1,"MM/yyyy")&" / "&"PAYSLIP "&TEXT(J1,"MM/yyyy") -> PHIẾU LƯƠNG THÁNG 05/2026 / PAYSLIP 05/2026 | J1: 46143 | K1: =DATE(YEAR(J1),MONTH(J1)-1,21) -> 46133 | L1: =DATE(YEAR(J1),MONTH(J1),20) -> 46162
A2: ="(Từ ngày "&TEXT(K1,"dd/MM/yyyy")&" đến ngày "&TEXT(L1,"dd/MM/yyyy")&")"&" / "&"(From "&TEXT(K1,"dd/MM/yyyy")&" to "&TEXT(L1,"dd/MM/yyyy")&")" -> (Từ ngày 21/04/2026 đến ngày 20/05/2026) / (From 21/04/2026 to 20/05/2026) | J2: .
A3: A. THÔNG TIN NHÂN VIÊN/ EMPLOYEE INFORMATION
A5: Tên nhân viên/ Full name | B5: Lê Văn Biên | F5: Loại HĐ/ Type of contract | G5: Chính thức/ Labor contract
A6: Mã số nhân viên/ Employee code | B6: 006720 | F6: Cấp bậc/ Level | G6: L6 | J6: chỉnh ngạch thành cấp bậc
A7: Chức danh/ Position | B7: Senior Construction Engineer / Giám sát chính Xây dựng
A8: Phòng ban/ Department | B8: Gia Binh International Airport / Sân bay Quốc tế Gia Bình
A9: Số người phụ thuộc/ Number of dependents | B9: 0 | C9: Người
A11: B. THÔNG TIN NGÀY CÔNG/ TIMESHEET INFORMATION
A12: Ngày công chuẩn/ Standard working days | B12: [0] | G12: 26 | I12: (Ngày/day)
A13: Ngày làm việc thực tế/ Actual working days | B13: [1] | G13: 26 | I13: (Ngày/day)
A14: Ngày làm việc hưởng 70% lương / Working days with 70% salary | B14: [2] | G14: 0 | I14: (Ngày/day)
A15: Ngày nghỉ lễ, tết/ Holidays | B15: [3] | G15: 0 | I15: (Ngày/day)
A16: Ngày nghỉ phép/ Annual leave | B16: [4] | G16: 0 | I16: (Ngày/day)
A17: Ngày nghỉ bù/ Rostered day off | B17: [5] | G17: 0 | I17: (Ngày/day)
A18: Ngày nghỉ chế độ (ma chay, hiếu hỉ)/ Paid leave | B18: [6] | G18: 0 | I18: (Ngày/day)
A19: Ngày nghỉ ốm Công ty/Company sick leave | B19: [7] | G19: 0 | I19: (Ngày/day) | J19: thêm
A20: Ngày nghỉ không hưởng lương/ unpaid leave | B20: [8] | G20: 0 | I20: (Ngày/day)
A21: Ngày chế độ BHXH/ SI paid leave | B21: [9] | G21: 0 | I21: (Ngày/day)
A22: Ngày công điều chỉnh/ Adjusted working days | G22: 0 | I22: (Ngày/day)
A23: Ngày phép tồn/ Leave balance | G23: 0 | I23: (Ngày/day)
A24: Tổng số ngày làm việc hưởng lương/ Total paid workdays | B24: [10] | G24: =G13+G14+G15+G16+G17+G19+G18 -> 26 | I24: (Ngày/day)
A27: C. THÔNG TIN LƯƠNG, PHỤ CẤP & TRỢ CẤP/ SALARY& ALLOWANCE INFORMATION
A28: Lương thử việc/ Probation salary | G28: 20000000 | I28: VND
A29: Lương chính thức/ Salary | G29: 20000000 | I29: VND
A30: Lương bình quân ngày/ Average salary per day | G30: =ROUND(G29/G12,0) -> 769231 | I30: VND | J30: hour nhưng cthuc đang là day
A31: Phụ cấp trách nhiệm/ Responsibility Allowance | G31: 0 | I31: VND
A32: Tổng lương thực tế trong tháng/ Total actual salary | B32: [11] | G32: 20000000 | I32: VND
A34: Phụ cấp/ Allowance | D34: Phụ cấp không chịu thuế/ Non-taxable allowance | G34: Phụ cấp chịu thuế/ Taxable allowance
A35: Phụ cấp cơm/ Meal | B35: [12] | D35: 730000 | F35: VND | G35: 2780000 | I35: VND
A36: Phụ cấp điện thoại/ Phone | B36: [13] | D36: 800000 | F36: VND | G36: 0 | I36: VND
A37: Phụ cấp NL/ Xăng/ Petrol | B37: [14] | D37: 0 | F37: VND | G37: 0 | I37: VND
A38: Phụ cấp đi lại/ Travel | B38: [15] | D38: 0 | F38: VND | G38: 0 | I38: VND
A39: Phụ cấp nhà ở/ Housing | B39: [16] | D39: 0 | F39: VND | G39: 0 | I39: VND
A40: Phụ cấp khác/ Other | B40: [17] | D40: 0 | F40: VND | G40: 0 | I40: VND
A41: Tổng tiền phụ cấp/ Total Allowance = [12+13+14+15+16+17] | B41: [18] | D41: =SUM(D35:D40) -> 1530000 | F41: VND | G41: =SUM(G35:G40) -> 2780000 | I41: VND
A44: Tăng ca/ Overtime | B44: Số giờ | D44: Lương tăng ca không chịu thuế | G44: Lương tăng ca chịu thuế
A45: Tăng ca ngày thường/ Weekday overtime [19] | B45: 0 | D45: 0 | F45: VND | G45: 0 | I45: VND
A46: Tăng ca ngày nghỉ/ Weekend overtime [20] | B46: 0 | D46: 0 | F46: VND | G46: 0 | I46: VND
A47: Tăng ca ngày lễ/ Holiday overtime [21] | B47: 0 | D47: 0 | F47: VND | G47: 0 | I47: VND
...

Sheet Master data
A1: Contract type
A2: # | B2: Name
A3: 1 | B3: Chính thức
A4: 2 | B4: Thử việc
A5: 3

Sheet Time Tracking Rule
A1: Loại | B1: Diễn giải | C1: Ví dụ
A2: Kỳ công | B2: Kỳ công tại CTD từ ngày 21 tháng này đến 20 tháng sau | C2: Kỳ công tháng 03/2026: từ ngày 21/02/2026 - 20/03/2026
A3: Ngày công chuẩn | B3: Văn phòng: tính từ ngày 21 - 20, trừ ngày chủ nhật và chiều thứ 7 Công trường: tính từ ngày 21 - 20, trừ ngày chủ nhật.
A4: Nghỉ phép năm | B4: 12 ngày/năm, cứ mỗi thời điểm đủ 05 năm làm việc liên tục tại công ty được cộng thêm 1 ngày phép (bao gồm thời gian thử việc)
B5: Mỗi tháng làm việc được tính 1 ngày phép. Người lao động làm việc chưa đủ tháng, nếu tổng số ngày làm việc và ngày nghỉ có hưởng lương chiếm tỷ lệ từ 50% trên công chuẩn tháng đó được tính 01 ngày phép trong tháng.
B6: Nếu book phép vượt quá số ngày phép định mức hiện có --> có cảnh báo và yêu cầu book trong định mức
B7: Nếu quản lý đã duyệt phép và người lao đông muốn hủy? - oke người lao động hủy trên hệ thống + mail cho quản lý
A8: Phép tồn | B8: Người lao động chưa sử dụng hết thời gian nghỉ hằng năm thì số ngày nghỉ còn lại sẽ được chuyển tiếp sang sử dụng đến hết ngày 31/12 của năm tiếp theo liền kề. Sau thời gian này, số ngày nghỉ hàng năm chưa sử dụng hết trong năm trước đó sẽ bị hủy bỏ và CBNV sẽ không được thanh toán lại bằng tiền.
B9: Người lao động làm việc chưa đủ 12 tháng tại Công ty thì số ngày nghỉ hằng năm theo tỷ lệ tương ứng với số tháng làm việc: lấy số ngày nghỉ hằng năm cộng với số ngày được nghỉ tăng thêm theo thâm niên (nếu có), chia cho 12 tháng, nhân với số tháng làm việc thực tế trong năm để tính thành số ngày được nghỉ hằng năm.
B10: CBNV đã ký hợp đồng lao động: Nghỉ việc được tổng hợp ngày phép tồn để tính lương phép
B11: CBNV đang thử việc: Nghỉ việc clear phép tồn, không tính lương phép tồn (được sử dụng trong thời gian thử việc nhưng ko dc tính phép tồn)
A12: Nghỉ không hưởng lương | B12: Khi Người lao động có nhu cầu nghỉ không hưởng lương để giải quyết việc riêng, Người lao động có thể gửi đơn trình bày lý do chính đáng, hợp lý lên các cấp Quản lý và Phòng Nhân sự - Tổng hợp xem xét giải quyết. Tùy trường hợp cụ thể mà Công ty có thể xem xét, quyết định giải quyết cho Người lao động được nghỉ không hưởng lương theo đơn xin nghỉ. Trong trường hợp này, Người lao động chỉ được nghỉ không hưởng lương khi đã có phê duyệt của Phòng Nhân sự - Tổng hợp & các cấp Quản lý theo phân quyền phê duyệt
A13: Nghỉ ốm (BHXH) | B13: Show Quy định BHXH để hướng dẫn book ốm + Lương hưởng: 75% lương bình quân đóng BHXH 6 tháng liền kề
B14: Con ốm: - Tối đa 20 ngày làm việc/năm nếu con < 3 tuổi - Tối đa 15 ngày làm việc/năm nếu con từu đủ 3 tuổi đến dưới 7 tuổi
B15: Bản thân ốm + Tối đa 30 ngày/năm, nếu đã đóng BHXH dưới 15 năm; + Tối đa 40 ngày/năm, nếu đã đóng BHXH từ đủ 15 năm đến dưới 30 năm; + Tối đa 60 ngày/năm, nếu đã đóng BHXH từ đủ 30 năm trở lên;
B16: Hồ sơ nghỉ hưởng: + nội trú: Giấy ra viện. + ngoại trú: Giấy nghỉ hưởng BHXH.
A17: Nghỉ ốm (Công ty) | B17: Định mức 03 ngày/năm dương lịch, mỗi lần nghỉ được book tối đa 01 ngày. Hết năm dương lịch hệ thống tự clear (không cộng dồn)
A18: Nghỉ thai sản | B18: Show quy định BHXH - hưởng 100% lương bình quân đóng BHXH 6 tháng liền kề. Lao động nam nghỉ (được nghỉ trong vòng 60 ngày đầu kể từ ngày vợ của Người lao động sinh con): + 05 ngày làm việc - vợ sinh thường 01 con; + 07 ngày làm việc khi vợ sinh con phải phẫu thuật, sinh con dưới 32 tuần tuổi; + Trường hợp vợ sinh đôi thì được nghỉ 10 ngày làm việc, từ sinh ba trở lên thì cứ thêm mỗi con được nghỉ thêm 03 (ba) ngày làm việc; hoặc Trường hợp vợ sinh đôi trở lên mà phải phẫu thuật thì được nghỉ 14 (mười bốn) ngày làm việc.
B19: Lao động nữ đẻ con: nghỉ 6 tháng. (nộp đơn trc 1 tháng) Lao động nữ khám thai: tối đa 02 ngày/lần, tối đa 10 ngày/thai kỳ
B20: Hồ sơ nghỉ hưởng: + Nam nghỉ: Giấy khai sinh/giấy chứng sinh thể hiện tên cha bản gốc hoặc sao y công chứng (nếu nghỉ 07 ngày thì có thêm giấy ra viện công chứng/bản gốc thể hiện sinh mổ) + Nữ khám thai: giấy chứng nhận nghỉ việc hưởng bảo hiểm xã hội + Nữ sinh con: Giấy khai sinh/giấy chứng sinh bản gốc hoặc sao y công chứng
A21: Nghỉ việc riêng có hưởng lương | B21: Show Định mức, công ty chi trả và cho book tối đa: + Bản thân Người lao động kết hôn nghỉ 03 ngày + Con đẻ, con nuôi kết hôn nghỉ 01 ngày + Tang chế Cha đẻ, mẹ đẻ, cha nuôi, mẹ nuôi; cha đẻ, mẹ đẻ, cha nuôi, mẹ nuôi của vợ hoặc chồng; vợ hoặc chồng; con đẻ, con nuôi chết nghỉ 03 ngày
A22: Nghỉ bù | B22: Trường hợp đi làm ngày nghỉ lễ (1) và được sắp xếp nghỉ bù --> cho theo dõi và khi nghỉ bù thì trừ dần. Định mức nghỉ bù được cộng dồn từ những ngày đi làm lễ, tết: 'Ngày nghỉ Lễ, Tết theo quy định của pháp luật: - Được trả thêm 100% tiền lương cho ngày làm Lễ, Tết. - Được bố trí 02 ngày nghỉ bù hưởng nguyên lương cho mỗi ngày làm việc. Ngày truyền thống Công ty (Coteccons Day), ngày nghỉ bổ sung do Công ty quyết định, ngày nghỉ bù do Lễ/Tết trùng vào ngày nghỉ hằng tuần: Được bố trí 01 ngày nghỉ bù hưởng nguyên lương cho mỗi ngày làm việc.
A23: Nghỉ lễ (1) | B23: - Cho set tự động + ngày 01 tháng 01 dương lịch + 05 ngày: 29 - 4/1 âm lịch (hoặc từ ngày 1/1-5/1 âm lịch) + Ngày Chiến thắng: 01 ngày 30/04 + Ngày Quốc tế lao động: 01 ngày 1/5 + Ngày Quốc khánh: 01 ngày 02/09 (thêm 1 ngày 01/09 hoặc 03/09) + Ngày Giỗ Tổ Hùng Vương: 01 ngày 10/03 âm lịch - Nếu cần chỉnh TRs vào chỉnh
A24: Đăng ký đi làm lễ | B24: Vào các ngày nghỉ lễ (1), nếu NLĐ đi làm thì cho đăng ký đi làm, cho phép NLĐ đăng ký/Thư ký import file --> trưởng bộ phận duyệt --> gửi về HR

Sheet References
A1: # | B1: Description | C1: Url
A2: 1 | B2: Agile | C2: What is Agile?
A3: 2 | B3: PGP Encryption | C3: What is PGP encryption?
A6: Methodology: Agile
A7: Sprint lenght: 2 weeks
A8: Sprint events: 1.Grooming 2. Review and Planning
A9: Dev - QCs events: 1. Kickoff 2. Demo
A10: Sprint Start:
A11: Management Tool: Atlassian JIRA
A13: Progressive TaxTable
A15: Tax rate | B15: From | C15: To | D15: Diff_Amount
A16: 0.05 | B16: 0 | C16: 5000000 | D16: 0
A17: 0.1 | B17: 5000000 | C17: 10000000 | D17: 250000
A19: 0.3 | B19: 52000000 | C19: 80000000 | D19: 5850000
A22: result=int((categories['ACCESSIBLE_INCOME']>100000000 and categories['ACCESSIBLE_INCOME']*0.35-14500000 or categories['ACCESSIBLE_INCOME']>60000000 and categories['ACCESSIBLE_INCOME']*0.3-9500000 or categories['ACCESSIBLE_INCOME']>30000000 and categories['ACCESSIBLE_INCOME']*0.2-3500000 or categories['ACCESSIBLE_INCOME']>10000000 and categories['ACCESSIBLE_INCOME']*0.1-500000 or categories['ACCESSIBLE_INCOME']>0 and categories['ACCESSIBLE_INCOME']*0.05 or 0)+0.5000001)

Sheet Handover Prerequisites
A1: What to demand BEFORE accepting
A2: 1. Knowledge Capture/Document request from the Current Dev
A3: # | B3: Item | C3: Why | D3: Priority | E3: Reviewer | F3: Provided on | G3: Reviewed on | H3: Assessment point | I3: Weight | J3: Score
A4: 1 | B4: Codebase walkthrough (recorded)/tech stack/FE/BE | C4: Only source of truth right now | D4: High | I4: 3 | J4: =IF(H4="","",VALUE(LEFT(H4,1)))*IF(D4="High",3,IF(D4="Medium",2,IF(D4="Low",1,""))) -> #VALUE!
A5: 2 | B5: Data model / DB schema | C5: Core of any payroll engine | D5: High | I5: 3 | J5: =IF(H5="","",VALUE(LEFT(H5,1)))*IF(D5="High",3,IF(D5="Medium",2,IF(D5="Low",1,""))) -> #VALUE!
A6: 3 | B6: Infrastructure | C6: Database/ Application/ Source code storage for each env | D6: High | I6: 3 | J6: =IF(H6="","",VALUE(LEFT(H6,1)))*IF(D6="High",3,IF(D6="Medium",2,IF(D6="Low",1,""))) -> #VALUE!
A7: 4 | B7: As-is/To-be flow | C7: To define what is a need and the ultimate goal | D7: High | I7: 3 | J7: =IF(H7="","",VALUE(LEFT(H7,1)))*IF(D7="High",3,IF(D7="Medium",2,IF(D7="Low",1,""))) -> #VALUE!
A8: 5 | B8: Business logic mapping (Excel → code) | C8: Most critical, hardest to reverse-engineer | D8: High | I8: 3 | J8: =IF(H8="","",VALUE(LEFT(H8,1)))*IF(D8="High",3,IF(D8="Medium",2,IF(D8="Low",1,""))) -> #VALUE!
A9: 6 | B9: Edge cases & known bugs | C9: Hidden landmines | D9: Medium | I9: 2 | J9: =IF(H9="","",VALUE(LEFT(H9,1)))*IF(D9="High",3,IF(D9="Medium",2,IF(D9="Low",1,""))) -> #VALUE!
A10: 7 | B10: Assumption Log | C10: What rules were assumed during build to be review and standard to user's test and GTM | D10: High | I10: 3 | J10: =IF(H10="","",VALUE(LEFT(H10,1)))*IF(D10="High",3,IF(D10="Medium",2,IF(D10="Low",1,""))) -> #VALUE!
A11: 8 | B11: Current deployment setup | C11: Avoid "works on my machine" | D11: Medium | I11: 2 | J11: =IF(H11="","",VALUE(LEFT(H11,1)))*IF(D11="High",3,IF(D11="Medium",2,IF(D11="Low",1,""))) -> #VALUE!
A12: 9 | B12: Any hardcoded CTD-specific configs | C12: Must be separated before Phase 2 | D12: Medium | I12: 2 | J12: =IF(H12="","",VALUE(LEFT(H12,1)))*IF(D12="High",3,IF(D12="Medium",2,IF(D12="Low",1,""))) -> #VALUE!
A13: 10 | B13: Payroll calculation formula walkthrough (step by step, not just code) | C13: Code alone doesn't tell you the intent behind the math — especially for PIT & BHXH | D13: High | I13: 3 | J13: =IF(H13="","",VALUE(LEFT(H13,1)))*IF(D13="High",3,IF(D13="Medium",2,IF(D13="Low",1,""))) -> #VALUE!
A14: 11 | B14: External dependencies / 3rd party integrations | C14: Are there any APIs, services, or external tools the system relies on? Must know before handover | D14: High | I14: 3 | J14: =IF(H14="","",VALUE(LEFT(H14,1)))*IF(D14="High",3,IF(D14="Medium",2,IF(D14="Low",1,""))) -> #VALUE!
A15: 12 | B15: Access & credentials handover (DB, server, env files) | C15: Often forgotten until it blocks the new team completely | D15: Medium | I15: 2 | J15: =IF(H15="","",VALUE(LEFT(H15,1)))*IF(D15="High",3,IF(D15="Medium",2,IF(D15="Low",1,""))) -> #VALUE!
A16: 13 | B16: User manual / how CTD currently uses the system | D16: Medium | I16: 2 | J16: =IF(H16="","",VALUE(LEFT(H16,1)))*IF(D16="High",3,IF(D16="Medium",2,IF(D16="Low",1,""))) -> #VALUE!
A17: 14 | B17: Environment setup guide | D17: Medium | I17: 2 | J17: =IF(H17="","",VALUE(LEFT(H17,1)))*IF(D17="High",3,IF(D17="Medium",2,IF(D17="Low",1,""))) -> #VALUE!
G18: Avg score | I18: =avg assessment point x weight of priority
A19: 2. Gap Analysis — What The Team Needs to Add
A20: # | B20: Gap | C20: Impact | D20: Action | E20: PIC
A21: 1 | B21: No BA | C21: Requirements unclear | D21: Assign 1 BA to reverse-document Phase 1
A22: 2 | B22: No technical specs | C22: Hard to handover and maintain | D22: (a) document current tech stack, (b) Tech Lead reviews and decides what stays vs gets replaced
A23: 3 | B23: No test suite | C23: Can't safely refactor | D23: Write regression tests before touching code
A24: 4 | B24: No product spec for Phase 2 | C24: Can't scope GTM | D24: Run a discovery sprint with stakeholders
A25: 5 | B25: 1 dev bus factor | C25: Immediate risk | D25: Parallel onboard a 2nd dev during knowledge transfer
A26: 6 | B26: No separation of CTD-specific logic | C26: Blocks Phase 2 | D26: Identify & modularize configs
A27: 7 | B27: No version control discipline | C27: If there's no branching strategy or commit standards, the 2nd dev onboarding will create conflicts immediately | I27: my assumsion so far, can confirm w Hau
A28: 8 | B28: No staging/UAT environment | C28: Payroll cannot be tested in production — a staging environment is non-negotiable | D28: Tech lead works w Devs to prep testing env | I28: my assumsion so far, can confirm w Hau
A29: 9 | B29: No error handling / audit log | C29: When payroll output is wrong, how does anyone know? Needs logging before Phase 2
